2020-04-06 19:23:31,900 ERROR: Exception on /index [GET] [in /home/nurbek/Desktop/microblog/env/lib/python3.7/site-packages/flask/app.py: 1891]
Traceback (most recent call last):
  File "/home/nurbek/Desktop/microblog/env/lib/python3.7/site-packages/flask/app.py", line 2446, in wsgi_app
    response = self.full_dispatch_request()
  File "/home/nurbek/Desktop/microblog/env/lib/python3.7/site-packages/flask/app.py", line 1951, in full_dispatch_request
    rv = self.handle_user_exception(e)
  File "/home/nurbek/Desktop/microblog/env/lib/python3.7/site-packages/flask/app.py", line 1820, in handle_user_exception
    reraise(exc_type, exc_value, tb)
  File "/home/nurbek/Desktop/microblog/env/lib/python3.7/site-packages/flask/_compat.py", line 39, in reraise
    raise value
  File "/home/nurbek/Desktop/microblog/env/lib/python3.7/site-packages/flask/app.py", line 1949, in full_dispatch_request
    rv = self.dispatch_request()
  File "/home/nurbek/Desktop/microblog/env/lib/python3.7/site-packages/flask/app.py", line 1935, in dispatch_request
    return self.view_functions[rule.endpoint](**req.view_args)
  File "/home/nurbek/Desktop/microblog/app/routes.py", line 22, in index
    posts = current_user.followed_post().all()
  File "/home/nurbek/Desktop/microblog/env/lib/python3.7/site-packages/werkzeug/local.py", line 347, in __getattr__
    return getattr(self._get_current_object(), name)
AttributeError: 'AnonymousUserMixin' object has no attribute 'followed_post'
2020-04-06 19:23:36,438 ERROR: Exception on /index [GET] [in /home/nurbek/Desktop/microblog/env/lib/python3.7/site-packages/flask/app.py: 1891]
Traceback (most recent call last):
  File "/home/nurbek/Desktop/microblog/env/lib/python3.7/site-packages/flask/app.py", line 2446, in wsgi_app
    response = self.full_dispatch_request()
  File "/home/nurbek/Desktop/microblog/env/lib/python3.7/site-packages/flask/app.py", line 1951, in full_dispatch_request
    rv = self.handle_user_exception(e)
  File "/home/nurbek/Desktop/microblog/env/lib/python3.7/site-packages/flask/app.py", line 1820, in handle_user_exception
    reraise(exc_type, exc_value, tb)
  File "/home/nurbek/Desktop/microblog/env/lib/python3.7/site-packages/flask/_compat.py", line 39, in reraise
    raise value
  File "/home/nurbek/Desktop/microblog/env/lib/python3.7/site-packages/flask/app.py", line 1949, in full_dispatch_request
    rv = self.dispatch_request()
  File "/home/nurbek/Desktop/microblog/env/lib/python3.7/site-packages/flask/app.py", line 1935, in dispatch_request
    return self.view_functions[rule.endpoint](**req.view_args)
  File "/home/nurbek/Desktop/microblog/app/routes.py", line 22, in index
    posts = current_user.followed_post().all()
  File "/home/nurbek/Desktop/microblog/env/lib/python3.7/site-packages/werkzeug/local.py", line 347, in __getattr__
    return getattr(self._get_current_object(), name)
AttributeError: 'AnonymousUserMixin' object has no attribute 'followed_post'
2020-04-06 19:26:41,033 INFO: Microblog [in /home/nurbek/Desktop/microblog/app/__init__.py: 48]
2020-04-06 19:26:44,755 ERROR: Exception on /index [GET] [in /home/nurbek/Desktop/microblog/env/lib/python3.7/site-packages/flask/app.py: 1891]
Traceback (most recent call last):
  File "/home/nurbek/Desktop/microblog/env/lib/python3.7/site-packages/flask/app.py", line 2446, in wsgi_app
    response = self.full_dispatch_request()
  File "/home/nurbek/Desktop/microblog/env/lib/python3.7/site-packages/flask/app.py", line 1951, in full_dispatch_request
    rv = self.handle_user_exception(e)
  File "/home/nurbek/Desktop/microblog/env/lib/python3.7/site-packages/flask/app.py", line 1820, in handle_user_exception
    reraise(exc_type, exc_value, tb)
  File "/home/nurbek/Desktop/microblog/env/lib/python3.7/site-packages/flask/_compat.py", line 39, in reraise
    raise value
  File "/home/nurbek/Desktop/microblog/env/lib/python3.7/site-packages/flask/app.py", line 1949, in full_dispatch_request
    rv = self.dispatch_request()
  File "/home/nurbek/Desktop/microblog/env/lib/python3.7/site-packages/flask/app.py", line 1935, in dispatch_request
    return self.view_functions[rule.endpoint](**req.view_args)
  File "/home/nurbek/Desktop/microblog/app/routes.py", line 22, in index
    posts = current_user.followed_post().all()
  File "/home/nurbek/Desktop/microblog/env/lib/python3.7/site-packages/werkzeug/local.py", line 347, in __getattr__
    return getattr(self._get_current_object(), name)
AttributeError: 'AnonymousUserMixin' object has no attribute 'followed_post'
2020-04-06 19:26:48,090 ERROR: Exception on /index [GET] [in /home/nurbek/Desktop/microblog/env/lib/python3.7/site-packages/flask/app.py: 1891]
Traceback (most recent call last):
  File "/home/nurbek/Desktop/microblog/env/lib/python3.7/site-packages/flask/app.py", line 2446, in wsgi_app
    response = self.full_dispatch_request()
  File "/home/nurbek/Desktop/microblog/env/lib/python3.7/site-packages/flask/app.py", line 1951, in full_dispatch_request
    rv = self.handle_user_exception(e)
  File "/home/nurbek/Desktop/microblog/env/lib/python3.7/site-packages/flask/app.py", line 1820, in handle_user_exception
    reraise(exc_type, exc_value, tb)
  File "/home/nurbek/Desktop/microblog/env/lib/python3.7/site-packages/flask/_compat.py", line 39, in reraise
    raise value
  File "/home/nurbek/Desktop/microblog/env/lib/python3.7/site-packages/flask/app.py", line 1949, in full_dispatch_request
    rv = self.dispatch_request()
  File "/home/nurbek/Desktop/microblog/env/lib/python3.7/site-packages/flask/app.py", line 1935, in dispatch_request
    return self.view_functions[rule.endpoint](**req.view_args)
  File "/home/nurbek/Desktop/microblog/app/routes.py", line 22, in index
    posts = current_user.followed_post().all()
  File "/home/nurbek/Desktop/microblog/env/lib/python3.7/site-packages/werkzeug/local.py", line 347, in __getattr__
    return getattr(self._get_current_object(), name)
AttributeError: 'AnonymousUserMixin' object has no attribute 'followed_post'
2020-04-06 19:28:07,704 ERROR: Exception on /index [GET] [in /home/nurbek/Desktop/microblog/env/lib/python3.7/site-packages/flask/app.py: 1891]
Traceback (most recent call last):
  File "/home/nurbek/Desktop/microblog/env/lib/python3.7/site-packages/flask/app.py", line 2446, in wsgi_app
    response = self.full_dispatch_request()
  File "/home/nurbek/Desktop/microblog/env/lib/python3.7/site-packages/flask/app.py", line 1951, in full_dispatch_request
    rv = self.handle_user_exception(e)
  File "/home/nurbek/Desktop/microblog/env/lib/python3.7/site-packages/flask/app.py", line 1820, in handle_user_exception
    reraise(exc_type, exc_value, tb)
  File "/home/nurbek/Desktop/microblog/env/lib/python3.7/site-packages/flask/_compat.py", line 39, in reraise
    raise value
  File "/home/nurbek/Desktop/microblog/env/lib/python3.7/site-packages/flask/app.py", line 1949, in full_dispatch_request
    rv = self.dispatch_request()
  File "/home/nurbek/Desktop/microblog/env/lib/python3.7/site-packages/flask/app.py", line 1935, in dispatch_request
    return self.view_functions[rule.endpoint](**req.view_args)
  File "/home/nurbek/Desktop/microblog/app/routes.py", line 22, in index
    posts = current_user.followed_post().all()
  File "/home/nurbek/Desktop/microblog/env/lib/python3.7/site-packages/werkzeug/local.py", line 347, in __getattr__
    return getattr(self._get_current_object(), name)
AttributeError: 'AnonymousUserMixin' object has no attribute 'followed_post'
2020-04-06 19:28:10,080 ERROR: Exception on /index [GET] [in /home/nurbek/Desktop/microblog/env/lib/python3.7/site-packages/flask/app.py: 1891]
Traceback (most recent call last):
  File "/home/nurbek/Desktop/microblog/env/lib/python3.7/site-packages/flask/app.py", line 2446, in wsgi_app
    response = self.full_dispatch_request()
  File "/home/nurbek/Desktop/microblog/env/lib/python3.7/site-packages/flask/app.py", line 1951, in full_dispatch_request
    rv = self.handle_user_exception(e)
  File "/home/nurbek/Desktop/microblog/env/lib/python3.7/site-packages/flask/app.py", line 1820, in handle_user_exception
    reraise(exc_type, exc_value, tb)
  File "/home/nurbek/Desktop/microblog/env/lib/python3.7/site-packages/flask/_compat.py", line 39, in reraise
    raise value
  File "/home/nurbek/Desktop/microblog/env/lib/python3.7/site-packages/flask/app.py", line 1949, in full_dispatch_request
    rv = self.dispatch_request()
  File "/home/nurbek/Desktop/microblog/env/lib/python3.7/site-packages/flask/app.py", line 1935, in dispatch_request
    return self.view_functions[rule.endpoint](**req.view_args)
  File "/home/nurbek/Desktop/microblog/app/routes.py", line 22, in index
    posts = current_user.followed_post().all()
  File "/home/nurbek/Desktop/microblog/env/lib/python3.7/site-packages/werkzeug/local.py", line 347, in __getattr__
    return getattr(self._get_current_object(), name)
AttributeError: 'AnonymousUserMixin' object has no attribute 'followed_post'
