2020-04-06 19:34:58,998 ERROR: Exception on / [GET] [in /home/nurbek/Desktop/microblog/env/lib/python3.7/site-packages/flask/app.py: 1891]
Traceback (most recent call last):
  File "/home/nurbek/Desktop/microblog/env/lib/python3.7/site-packages/flask/app.py", line 2446, in wsgi_app
    response = self.full_dispatch_request()
  File "/home/nurbek/Desktop/microblog/env/lib/python3.7/site-packages/flask/app.py", line 1951, in full_dispatch_request
    rv = self.handle_user_exception(e)
  File "/home/nurbek/Desktop/microblog/env/lib/python3.7/site-packages/flask/app.py", line 1820, in handle_user_exception
    reraise(exc_type, exc_value, tb)
  File "/home/nurbek/Desktop/microblog/env/lib/python3.7/site-packages/flask/_compat.py", line 39, in reraise
    raise value
  File "/home/nurbek/Desktop/microblog/env/lib/python3.7/site-packages/flask/app.py", line 1949, in full_dispatch_request
    rv = self.dispatch_request()
  File "/home/nurbek/Desktop/microblog/env/lib/python3.7/site-packages/flask/app.py", line 1935, in dispatch_request
    return self.view_functions[rule.endpoint](**req.view_args)
  File "/home/nurbek/Desktop/microblog/app/routes.py", line 22, in index
    posts = current_user.followed_post().all()
  File "/home/nurbek/Desktop/microblog/env/lib/python3.7/site-packages/werkzeug/local.py", line 347, in __getattr__
    return getattr(self._get_current_object(), name)
AttributeError: 'AnonymousUserMixin' object has no attribute 'followed_post'
2020-04-06 19:35:01,685 ERROR: Exception on / [GET] [in /home/nurbek/Desktop/microblog/env/lib/python3.7/site-packages/flask/app.py: 1891]
Traceback (most recent call last):
  File "/home/nurbek/Desktop/microblog/env/lib/python3.7/site-packages/flask/app.py", line 2446, in wsgi_app
    response = self.full_dispatch_request()
  File "/home/nurbek/Desktop/microblog/env/lib/python3.7/site-packages/flask/app.py", line 1951, in full_dispatch_request
    rv = self.handle_user_exception(e)
  File "/home/nurbek/Desktop/microblog/env/lib/python3.7/site-packages/flask/app.py", line 1820, in handle_user_exception
    reraise(exc_type, exc_value, tb)
  File "/home/nurbek/Desktop/microblog/env/lib/python3.7/site-packages/flask/_compat.py", line 39, in reraise
    raise value
  File "/home/nurbek/Desktop/microblog/env/lib/python3.7/site-packages/flask/app.py", line 1949, in full_dispatch_request
    rv = self.dispatch_request()
  File "/home/nurbek/Desktop/microblog/env/lib/python3.7/site-packages/flask/app.py", line 1935, in dispatch_request
    return self.view_functions[rule.endpoint](**req.view_args)
  File "/home/nurbek/Desktop/microblog/app/routes.py", line 22, in index
    posts = current_user.followed_post().all()
  File "/home/nurbek/Desktop/microblog/env/lib/python3.7/site-packages/werkzeug/local.py", line 347, in __getattr__
    return getattr(self._get_current_object(), name)
AttributeError: 'AnonymousUserMixin' object has no attribute 'followed_post'
2020-04-06 19:35:02,463 ERROR: Exception on / [GET] [in /home/nurbek/Desktop/microblog/env/lib/python3.7/site-packages/flask/app.py: 1891]
Traceback (most recent call last):
  File "/home/nurbek/Desktop/microblog/env/lib/python3.7/site-packages/flask/app.py", line 2446, in wsgi_app
    response = self.full_dispatch_request()
  File "/home/nurbek/Desktop/microblog/env/lib/python3.7/site-packages/flask/app.py", line 1951, in full_dispatch_request
    rv = self.handle_user_exception(e)
  File "/home/nurbek/Desktop/microblog/env/lib/python3.7/site-packages/flask/app.py", line 1820, in handle_user_exception
    reraise(exc_type, exc_value, tb)
  File "/home/nurbek/Desktop/microblog/env/lib/python3.7/site-packages/flask/_compat.py", line 39, in reraise
    raise value
  File "/home/nurbek/Desktop/microblog/env/lib/python3.7/site-packages/flask/app.py", line 1949, in full_dispatch_request
    rv = self.dispatch_request()
  File "/home/nurbek/Desktop/microblog/env/lib/python3.7/site-packages/flask/app.py", line 1935, in dispatch_request
    return self.view_functions[rule.endpoint](**req.view_args)
  File "/home/nurbek/Desktop/microblog/app/routes.py", line 22, in index
    posts = current_user.followed_post().all()
  File "/home/nurbek/Desktop/microblog/env/lib/python3.7/site-packages/werkzeug/local.py", line 347, in __getattr__
    return getattr(self._get_current_object(), name)
AttributeError: 'AnonymousUserMixin' object has no attribute 'followed_post'
2020-04-06 19:35:40,163 INFO: Microblog [in /home/nurbek/Desktop/microblog/app/__init__.py: 48]
2020-04-06 19:35:42,942 ERROR: Exception on / [GET] [in /home/nurbek/Desktop/microblog/env/lib/python3.7/site-packages/flask/app.py: 1891]
Traceback (most recent call last):
  File "/home/nurbek/Desktop/microblog/env/lib/python3.7/site-packages/flask/app.py", line 2446, in wsgi_app
    response = self.full_dispatch_request()
  File "/home/nurbek/Desktop/microblog/env/lib/python3.7/site-packages/flask/app.py", line 1951, in full_dispatch_request
    rv = self.handle_user_exception(e)
  File "/home/nurbek/Desktop/microblog/env/lib/python3.7/site-packages/flask/app.py", line 1820, in handle_user_exception
    reraise(exc_type, exc_value, tb)
  File "/home/nurbek/Desktop/microblog/env/lib/python3.7/site-packages/flask/_compat.py", line 39, in reraise
    raise value
  File "/home/nurbek/Desktop/microblog/env/lib/python3.7/site-packages/flask/app.py", line 1949, in full_dispatch_request
    rv = self.dispatch_request()
  File "/home/nurbek/Desktop/microblog/env/lib/python3.7/site-packages/flask/app.py", line 1935, in dispatch_request
    return self.view_functions[rule.endpoint](**req.view_args)
  File "/home/nurbek/Desktop/microblog/app/routes.py", line 24, in index
    return render_template('index.html', title='Home', posts=posts, form=form)
UnboundLocalError: local variable 'posts' referenced before assignment
2020-04-06 19:35:45,462 ERROR: Exception on / [GET] [in /home/nurbek/Desktop/microblog/env/lib/python3.7/site-packages/flask/app.py: 1891]
Traceback (most recent call last):
  File "/home/nurbek/Desktop/microblog/env/lib/python3.7/site-packages/flask/app.py", line 2446, in wsgi_app
    response = self.full_dispatch_request()
  File "/home/nurbek/Desktop/microblog/env/lib/python3.7/site-packages/flask/app.py", line 1951, in full_dispatch_request
    rv = self.handle_user_exception(e)
  File "/home/nurbek/Desktop/microblog/env/lib/python3.7/site-packages/flask/app.py", line 1820, in handle_user_exception
    reraise(exc_type, exc_value, tb)
  File "/home/nurbek/Desktop/microblog/env/lib/python3.7/site-packages/flask/_compat.py", line 39, in reraise
    raise value
  File "/home/nurbek/Desktop/microblog/env/lib/python3.7/site-packages/flask/app.py", line 1949, in full_dispatch_request
    rv = self.dispatch_request()
  File "/home/nurbek/Desktop/microblog/env/lib/python3.7/site-packages/flask/app.py", line 1935, in dispatch_request
    return self.view_functions[rule.endpoint](**req.view_args)
  File "/home/nurbek/Desktop/microblog/app/routes.py", line 24, in index
    return render_template('index.html', title='Home', posts=posts, form=form)
UnboundLocalError: local variable 'posts' referenced before assignment
2020-04-06 19:37:02,289 INFO: Microblog [in /home/nurbek/Desktop/microblog/app/__init__.py: 48]
2020-04-06 19:37:07,877 ERROR: Exception on / [GET] [in /home/nurbek/Desktop/microblog/env/lib/python3.7/site-packages/flask/app.py: 1891]
Traceback (most recent call last):
  File "/home/nurbek/Desktop/microblog/env/lib/python3.7/site-packages/flask/app.py", line 2446, in wsgi_app
    response = self.full_dispatch_request()
  File "/home/nurbek/Desktop/microblog/env/lib/python3.7/site-packages/flask/app.py", line 1951, in full_dispatch_request
    rv = self.handle_user_exception(e)
  File "/home/nurbek/Desktop/microblog/env/lib/python3.7/site-packages/flask/app.py", line 1820, in handle_user_exception
    reraise(exc_type, exc_value, tb)
  File "/home/nurbek/Desktop/microblog/env/lib/python3.7/site-packages/flask/_compat.py", line 39, in reraise
    raise value
  File "/home/nurbek/Desktop/microblog/env/lib/python3.7/site-packages/flask/app.py", line 1949, in full_dispatch_request
    rv = self.dispatch_request()
  File "/home/nurbek/Desktop/microblog/env/lib/python3.7/site-packages/flask/app.py", line 1935, in dispatch_request
    return self.view_functions[rule.endpoint](**req.view_args)
  File "/home/nurbek/Desktop/microblog/app/routes.py", line 23, in index
    return render_template('index.html', title='Home', posts=posts, form=form)
UnboundLocalError: local variable 'posts' referenced before assignment
2020-04-06 19:37:10,722 ERROR: Exception on / [GET] [in /home/nurbek/Desktop/microblog/env/lib/python3.7/site-packages/flask/app.py: 1891]
Traceback (most recent call last):
  File "/home/nurbek/Desktop/microblog/env/lib/python3.7/site-packages/flask/app.py", line 2446, in wsgi_app
    response = self.full_dispatch_request()
  File "/home/nurbek/Desktop/microblog/env/lib/python3.7/site-packages/flask/app.py", line 1951, in full_dispatch_request
    rv = self.handle_user_exception(e)
  File "/home/nurbek/Desktop/microblog/env/lib/python3.7/site-packages/flask/app.py", line 1820, in handle_user_exception
    reraise(exc_type, exc_value, tb)
  File "/home/nurbek/Desktop/microblog/env/lib/python3.7/site-packages/flask/_compat.py", line 39, in reraise
    raise value
  File "/home/nurbek/Desktop/microblog/env/lib/python3.7/site-packages/flask/app.py", line 1949, in full_dispatch_request
    rv = self.dispatch_request()
  File "/home/nurbek/Desktop/microblog/env/lib/python3.7/site-packages/flask/app.py", line 1935, in dispatch_request
    return self.view_functions[rule.endpoint](**req.view_args)
  File "/home/nurbek/Desktop/microblog/app/routes.py", line 23, in index
    return render_template('index.html', title='Home', posts=posts, form=form)
UnboundLocalError: local variable 'posts' referenced before assignment
