2020-04-13 20:09:25,405 ERROR: Exception on / [GET] [in /home/nurbek/Desktop/microblog/env/lib/python3.7/site-packages/flask/app.py: 1891]
Traceback (most recent call last):
  File "/home/nurbek/Desktop/microblog/env/lib/python3.7/site-packages/flask/app.py", line 2446, in wsgi_app
    response = self.full_dispatch_request()
  File "/home/nurbek/Desktop/microblog/env/lib/python3.7/site-packages/flask/app.py", line 1951, in full_dispatch_request
    rv = self.handle_user_exception(e)
  File "/home/nurbek/Desktop/microblog/env/lib/python3.7/site-packages/flask/app.py", line 1820, in handle_user_exception
    reraise(exc_type, exc_value, tb)
  File "/home/nurbek/Desktop/microblog/env/lib/python3.7/site-packages/flask/_compat.py", line 39, in reraise
    raise value
  File "/home/nurbek/Desktop/microblog/env/lib/python3.7/site-packages/flask/app.py", line 1947, in full_dispatch_request
    rv = self.preprocess_request()
  File "/home/nurbek/Desktop/microblog/env/lib/python3.7/site-packages/flask/app.py", line 2241, in preprocess_request
    rv = func()
  File "/home/nurbek/Desktop/microblog/app/main/routes.py", line 52, in before_request
    g.locale = str(get_locale())
  File "/home/nurbek/Desktop/microblog/env/lib/python3.7/site-packages/flask_babel/__init__.py", line 251, in get_locale
    rv = babel.locale_selector_func()
  File "/home/nurbek/Desktop/microblog/app/__init__.py", line 82, in get_locale
    return request.accept_languages.best_match(app.config['LANGUAGES'])
NameError: name 'app' is not defined
2020-04-13 20:11:08,715 INFO: Microblog [in /home/nurbek/Desktop/microblog/app/__init__.py: 75]
2020-04-13 20:11:11,162 ERROR: Exception on / [GET] [in /home/nurbek/Desktop/microblog/env/lib/python3.7/site-packages/flask/app.py: 1891]
Traceback (most recent call last):
  File "/home/nurbek/Desktop/microblog/env/lib/python3.7/site-packages/flask/app.py", line 2446, in wsgi_app
    response = self.full_dispatch_request()
  File "/home/nurbek/Desktop/microblog/env/lib/python3.7/site-packages/flask/app.py", line 1951, in full_dispatch_request
    rv = self.handle_user_exception(e)
  File "/home/nurbek/Desktop/microblog/env/lib/python3.7/site-packages/flask/app.py", line 1820, in handle_user_exception
    reraise(exc_type, exc_value, tb)
  File "/home/nurbek/Desktop/microblog/env/lib/python3.7/site-packages/flask/_compat.py", line 39, in reraise
    raise value
  File "/home/nurbek/Desktop/microblog/env/lib/python3.7/site-packages/flask/app.py", line 1949, in full_dispatch_request
    rv = self.dispatch_request()
  File "/home/nurbek/Desktop/microblog/env/lib/python3.7/site-packages/flask/app.py", line 1935, in dispatch_request
    return self.view_functions[rule.endpoint](**req.view_args)
  File "/home/nurbek/Desktop/microblog/env/lib/python3.7/site-packages/flask_login/utils.py", line 271, in decorated_view
    return current_app.login_manager.unauthorized()
  File "/home/nurbek/Desktop/microblog/env/lib/python3.7/site-packages/flask_login/login_manager.py", line 174, in unauthorized
    redirect_url = make_login_url(login_view, next_url=request.url)
  File "/home/nurbek/Desktop/microblog/env/lib/python3.7/site-packages/flask_login/utils.py", line 120, in login_url
    base = expand_login_view(login_view)
  File "/home/nurbek/Desktop/microblog/env/lib/python3.7/site-packages/flask_login/utils.py", line 97, in expand_login_view
    return url_for(login_view)
  File "/home/nurbek/Desktop/microblog/env/lib/python3.7/site-packages/flask/helpers.py", line 370, in url_for
    return appctx.app.handle_url_build_error(error, endpoint, values)
  File "/home/nurbek/Desktop/microblog/env/lib/python3.7/site-packages/flask/app.py", line 2215, in handle_url_build_error
    reraise(exc_type, exc_value, tb)
  File "/home/nurbek/Desktop/microblog/env/lib/python3.7/site-packages/flask/_compat.py", line 39, in reraise
    raise value
  File "/home/nurbek/Desktop/microblog/env/lib/python3.7/site-packages/flask/helpers.py", line 358, in url_for
    endpoint, values, method=method, force_external=external
  File "/home/nurbek/Desktop/microblog/env/lib/python3.7/site-packages/werkzeug/routing.py", line 2179, in build
    raise BuildError(endpoint, values, method, self)
werkzeug.routing.BuildError: Could not build url for endpoint 'login'. Did you mean 'auth.login' instead?
2020-04-13 20:13:34,642 ERROR: Exception on / [GET] [in /home/nurbek/Desktop/microblog/env/lib/python3.7/site-packages/flask/app.py: 1891]
Traceback (most recent call last):
  File "/home/nurbek/Desktop/microblog/env/lib/python3.7/site-packages/flask/app.py", line 2446, in wsgi_app
    response = self.full_dispatch_request()
  File "/home/nurbek/Desktop/microblog/env/lib/python3.7/site-packages/flask/app.py", line 1951, in full_dispatch_request
    rv = self.handle_user_exception(e)
  File "/home/nurbek/Desktop/microblog/env/lib/python3.7/site-packages/flask/app.py", line 1820, in handle_user_exception
    reraise(exc_type, exc_value, tb)
  File "/home/nurbek/Desktop/microblog/env/lib/python3.7/site-packages/flask/_compat.py", line 39, in reraise
    raise value
  File "/home/nurbek/Desktop/microblog/env/lib/python3.7/site-packages/flask/app.py", line 1949, in full_dispatch_request
    rv = self.dispatch_request()
  File "/home/nurbek/Desktop/microblog/env/lib/python3.7/site-packages/flask/app.py", line 1935, in dispatch_request
    return self.view_functions[rule.endpoint](**req.view_args)
  File "/home/nurbek/Desktop/microblog/env/lib/python3.7/site-packages/flask_login/utils.py", line 271, in decorated_view
    return current_app.login_manager.unauthorized()
  File "/home/nurbek/Desktop/microblog/env/lib/python3.7/site-packages/flask_login/login_manager.py", line 174, in unauthorized
    redirect_url = make_login_url(login_view, next_url=request.url)
  File "/home/nurbek/Desktop/microblog/env/lib/python3.7/site-packages/flask_login/utils.py", line 120, in login_url
    base = expand_login_view(login_view)
  File "/home/nurbek/Desktop/microblog/env/lib/python3.7/site-packages/flask_login/utils.py", line 97, in expand_login_view
    return url_for(login_view)
  File "/home/nurbek/Desktop/microblog/env/lib/python3.7/site-packages/flask/helpers.py", line 370, in url_for
    return appctx.app.handle_url_build_error(error, endpoint, values)
  File "/home/nurbek/Desktop/microblog/env/lib/python3.7/site-packages/flask/app.py", line 2215, in handle_url_build_error
    reraise(exc_type, exc_value, tb)
  File "/home/nurbek/Desktop/microblog/env/lib/python3.7/site-packages/flask/_compat.py", line 39, in reraise
    raise value
  File "/home/nurbek/Desktop/microblog/env/lib/python3.7/site-packages/flask/helpers.py", line 358, in url_for
    endpoint, values, method=method, force_external=external
  File "/home/nurbek/Desktop/microblog/env/lib/python3.7/site-packages/werkzeug/routing.py", line 2179, in build
    raise BuildError(endpoint, values, method, self)
werkzeug.routing.BuildError: Could not build url for endpoint 'login'. Did you mean 'auth.login' instead?
2020-04-13 20:13:52,707 INFO: Microblog [in /home/nurbek/Desktop/microblog/app/__init__.py: 75]
2020-04-13 20:13:55,076 ERROR: Exception on / [GET] [in /home/nurbek/Desktop/microblog/env/lib/python3.7/site-packages/flask/app.py: 1891]
Traceback (most recent call last):
  File "/home/nurbek/Desktop/microblog/env/lib/python3.7/site-packages/flask/app.py", line 2446, in wsgi_app
    response = self.full_dispatch_request()
  File "/home/nurbek/Desktop/microblog/env/lib/python3.7/site-packages/flask/app.py", line 1951, in full_dispatch_request
    rv = self.handle_user_exception(e)
  File "/home/nurbek/Desktop/microblog/env/lib/python3.7/site-packages/flask/app.py", line 1820, in handle_user_exception
    reraise(exc_type, exc_value, tb)
  File "/home/nurbek/Desktop/microblog/env/lib/python3.7/site-packages/flask/_compat.py", line 39, in reraise
    raise value
  File "/home/nurbek/Desktop/microblog/env/lib/python3.7/site-packages/flask/app.py", line 1949, in full_dispatch_request
    rv = self.dispatch_request()
  File "/home/nurbek/Desktop/microblog/env/lib/python3.7/site-packages/flask/app.py", line 1935, in dispatch_request
    return self.view_functions[rule.endpoint](**req.view_args)
  File "/home/nurbek/Desktop/microblog/env/lib/python3.7/site-packages/flask_login/utils.py", line 271, in decorated_view
    return current_app.login_manager.unauthorized()
  File "/home/nurbek/Desktop/microblog/env/lib/python3.7/site-packages/flask_login/login_manager.py", line 174, in unauthorized
    redirect_url = make_login_url(login_view, next_url=request.url)
  File "/home/nurbek/Desktop/microblog/env/lib/python3.7/site-packages/flask_login/utils.py", line 120, in login_url
    base = expand_login_view(login_view)
  File "/home/nurbek/Desktop/microblog/env/lib/python3.7/site-packages/flask_login/utils.py", line 97, in expand_login_view
    return url_for(login_view)
  File "/home/nurbek/Desktop/microblog/env/lib/python3.7/site-packages/flask/helpers.py", line 370, in url_for
    return appctx.app.handle_url_build_error(error, endpoint, values)
  File "/home/nurbek/Desktop/microblog/env/lib/python3.7/site-packages/flask/app.py", line 2215, in handle_url_build_error
    reraise(exc_type, exc_value, tb)
  File "/home/nurbek/Desktop/microblog/env/lib/python3.7/site-packages/flask/_compat.py", line 39, in reraise
    raise value
  File "/home/nurbek/Desktop/microblog/env/lib/python3.7/site-packages/flask/helpers.py", line 358, in url_for
    endpoint, values, method=method, force_external=external
  File "/home/nurbek/Desktop/microblog/env/lib/python3.7/site-packages/werkzeug/routing.py", line 2179, in build
    raise BuildError(endpoint, values, method, self)
werkzeug.routing.BuildError: Could not build url for endpoint 'login'. Did you mean 'auth.login' instead?
2020-04-13 20:14:20,818 INFO: Microblog [in /home/nurbek/Desktop/microblog/app/__init__.py: 75]
