2020-04-02 21:30:35,996 ERROR: Exception on /edit_profile [POST] [in /home/nurbek/Desktop/microblog/env/lib/python3.7/site-packages/flask/app.py: 1891]
Traceback (most recent call last):
  File "/home/nurbek/Desktop/microblog/env/lib/python3.7/site-packages/sqlalchemy/engine/base.py", line 1248, in _execute_context
    cursor, statement, parameters, context
  File "/home/nurbek/Desktop/microblog/env/lib/python3.7/site-packages/sqlalchemy/engine/default.py", line 588, in do_execute
    cursor.execute(statement, parameters)
sqlite3.IntegrityError: UNIQUE constraint failed: users.username

The above exception was the direct cause of the following exception:

Traceback (most recent call last):
  File "/home/nurbek/Desktop/microblog/env/lib/python3.7/site-packages/flask/app.py", line 2446, in wsgi_app
    response = self.full_dispatch_request()
  File "/home/nurbek/Desktop/microblog/env/lib/python3.7/site-packages/flask/app.py", line 1951, in full_dispatch_request
    rv = self.handle_user_exception(e)
  File "/home/nurbek/Desktop/microblog/env/lib/python3.7/site-packages/flask/app.py", line 1820, in handle_user_exception
    reraise(exc_type, exc_value, tb)
  File "/home/nurbek/Desktop/microblog/env/lib/python3.7/site-packages/flask/_compat.py", line 39, in reraise
    raise value
  File "/home/nurbek/Desktop/microblog/env/lib/python3.7/site-packages/flask/app.py", line 1949, in full_dispatch_request
    rv = self.dispatch_request()
  File "/home/nurbek/Desktop/microblog/env/lib/python3.7/site-packages/flask/app.py", line 1935, in dispatch_request
    return self.view_functions[rule.endpoint](**req.view_args)
  File "/home/nurbek/Desktop/microblog/app/routes.py", line 93, in edit_profile
    db.session.commit()
  File "/home/nurbek/Desktop/microblog/env/lib/python3.7/site-packages/sqlalchemy/orm/scoping.py", line 162, in do
    return getattr(self.registry(), name)(*args, **kwargs)
  File "/home/nurbek/Desktop/microblog/env/lib/python3.7/site-packages/sqlalchemy/orm/session.py", line 1036, in commit
    self.transaction.commit()
  File "/home/nurbek/Desktop/microblog/env/lib/python3.7/site-packages/sqlalchemy/orm/session.py", line 503, in commit
    self._prepare_impl()
  File "/home/nurbek/Desktop/microblog/env/lib/python3.7/site-packages/sqlalchemy/orm/session.py", line 482, in _prepare_impl
    self.session.flush()
  File "/home/nurbek/Desktop/microblog/env/lib/python3.7/site-packages/sqlalchemy/orm/session.py", line 2496, in flush
    self._flush(objects)
  File "/home/nurbek/Desktop/microblog/env/lib/python3.7/site-packages/sqlalchemy/orm/session.py", line 2637, in _flush
    transaction.rollback(_capture_exception=True)
  File "/home/nurbek/Desktop/microblog/env/lib/python3.7/site-packages/sqlalchemy/util/langhelpers.py", line 69, in __exit__
    exc_value, with_traceback=exc_tb,
  File "/home/nurbek/Desktop/microblog/env/lib/python3.7/site-packages/sqlalchemy/util/compat.py", line 178, in raise_
    raise exception
  File "/home/nurbek/Desktop/microblog/env/lib/python3.7/site-packages/sqlalchemy/orm/session.py", line 2597, in _flush
    flush_context.execute()
  File "/home/nurbek/Desktop/microblog/env/lib/python3.7/site-packages/sqlalchemy/orm/unitofwork.py", line 422, in execute
    rec.execute(self)
  File "/home/nurbek/Desktop/microblog/env/lib/python3.7/site-packages/sqlalchemy/orm/unitofwork.py", line 589, in execute
    uow,
  File "/home/nurbek/Desktop/microblog/env/lib/python3.7/site-packages/sqlalchemy/orm/persistence.py", line 236, in save_obj
    update,
  File "/home/nurbek/Desktop/microblog/env/lib/python3.7/site-packages/sqlalchemy/orm/persistence.py", line 995, in _emit_update_statements
    statement, multiparams
  File "/home/nurbek/Desktop/microblog/env/lib/python3.7/site-packages/sqlalchemy/engine/base.py", line 984, in execute
    return meth(self, multiparams, params)
  File "/home/nurbek/Desktop/microblog/env/lib/python3.7/site-packages/sqlalchemy/sql/elements.py", line 293, in _execute_on_connection
    return connection._execute_clauseelement(self, multiparams, params)
  File "/home/nurbek/Desktop/microblog/env/lib/python3.7/site-packages/sqlalchemy/engine/base.py", line 1103, in _execute_clauseelement
    distilled_params,
  File "/home/nurbek/Desktop/microblog/env/lib/python3.7/site-packages/sqlalchemy/engine/base.py", line 1288, in _execute_context
    e, statement, parameters, cursor, context
  File "/home/nurbek/Desktop/microblog/env/lib/python3.7/site-packages/sqlalchemy/engine/base.py", line 1482, in _handle_dbapi_exception
    sqlalchemy_exception, with_traceback=exc_info[2], from_=e
  File "/home/nurbek/Desktop/microblog/env/lib/python3.7/site-packages/sqlalchemy/util/compat.py", line 178, in raise_
    raise exception
  File "/home/nurbek/Desktop/microblog/env/lib/python3.7/site-packages/sqlalchemy/engine/base.py", line 1248, in _execute_context
    cursor, statement, parameters, context
  File "/home/nurbek/Desktop/microblog/env/lib/python3.7/site-packages/sqlalchemy/engine/default.py", line 588, in do_execute
    cursor.execute(statement, parameters)
sqlalchemy.exc.IntegrityError: (sqlite3.IntegrityError) UNIQUE constraint failed: users.username
[SQL: UPDATE users SET username=?, about_me=? WHERE users.id = ?]
[parameters: ('Kanat', 'I am Python menthor in Makers BootCamp. Edited.\r\nOne more adited profile.', 3)]
(Background on this error at: http://sqlalche.me/e/gkpj)
2020-04-03 19:48:16,453 INFO: Microblog [in /home/nurbek/Desktop/microblog/app/__init__.py: 48]
2020-04-03 19:48:53,823 INFO: Microblog [in /home/nurbek/Desktop/microblog/app/__init__.py: 48]
2020-04-03 19:49:53,848 INFO: Microblog [in /home/nurbek/Desktop/microblog/app/__init__.py: 48]
2020-04-03 19:50:00,393 INFO: Microblog [in /home/nurbek/Desktop/microblog/app/__init__.py: 48]
2020-04-03 19:56:20,100 INFO: Microblog [in /home/nurbek/Desktop/microblog/app/__init__.py: 48]
2020-04-03 20:56:04,315 INFO: Microblog [in /home/nurbek/Desktop/microblog/app/__init__.py: 48]
2020-04-03 20:56:30,335 INFO: Microblog [in /home/nurbek/Desktop/microblog/app/__init__.py: 48]
2020-04-03 20:58:35,887 INFO: Microblog [in /home/nurbek/Desktop/microblog/app/__init__.py: 48]
2020-04-03 21:01:40,639 INFO: Microblog [in /home/nurbek/Desktop/microblog/app/__init__.py: 48]
2020-04-06 19:02:31,207 INFO: Microblog [in /home/nurbek/Desktop/microblog/app/__init__.py: 48]
2020-04-06 19:19:45,013 INFO: Microblog [in /home/nurbek/Desktop/microblog/app/__init__.py: 48]
2020-04-06 19:19:47,310 ERROR: Exception on / [GET] [in /home/nurbek/Desktop/microblog/env/lib/python3.7/site-packages/flask/app.py: 1891]
Traceback (most recent call last):
  File "/home/nurbek/Desktop/microblog/env/lib/python3.7/site-packages/flask/app.py", line 2446, in wsgi_app
    response = self.full_dispatch_request()
  File "/home/nurbek/Desktop/microblog/env/lib/python3.7/site-packages/flask/app.py", line 1951, in full_dispatch_request
    rv = self.handle_user_exception(e)
  File "/home/nurbek/Desktop/microblog/env/lib/python3.7/site-packages/flask/app.py", line 1820, in handle_user_exception
    reraise(exc_type, exc_value, tb)
  File "/home/nurbek/Desktop/microblog/env/lib/python3.7/site-packages/flask/_compat.py", line 39, in reraise
    raise value
  File "/home/nurbek/Desktop/microblog/env/lib/python3.7/site-packages/flask/app.py", line 1949, in full_dispatch_request
    rv = self.dispatch_request()
  File "/home/nurbek/Desktop/microblog/env/lib/python3.7/site-packages/flask/app.py", line 1935, in dispatch_request
    return self.view_functions[rule.endpoint](**req.view_args)
  File "/home/nurbek/Desktop/microblog/app/routes.py", line 22, in index
    posts = current_user.followed_posts().all()
  File "/home/nurbek/Desktop/microblog/env/lib/python3.7/site-packages/werkzeug/local.py", line 347, in __getattr__
    return getattr(self._get_current_object(), name)
AttributeError: 'AnonymousUserMixin' object has no attribute 'followed_posts'
2020-04-06 19:20:12,680 ERROR: Exception on /index [GET] [in /home/nurbek/Desktop/microblog/env/lib/python3.7/site-packages/flask/app.py: 1891]
Traceback (most recent call last):
  File "/home/nurbek/Desktop/microblog/env/lib/python3.7/site-packages/flask/app.py", line 2446, in wsgi_app
    response = self.full_dispatch_request()
  File "/home/nurbek/Desktop/microblog/env/lib/python3.7/site-packages/flask/app.py", line 1951, in full_dispatch_request
    rv = self.handle_user_exception(e)
  File "/home/nurbek/Desktop/microblog/env/lib/python3.7/site-packages/flask/app.py", line 1820, in handle_user_exception
    reraise(exc_type, exc_value, tb)
  File "/home/nurbek/Desktop/microblog/env/lib/python3.7/site-packages/flask/_compat.py", line 39, in reraise
    raise value
  File "/home/nurbek/Desktop/microblog/env/lib/python3.7/site-packages/flask/app.py", line 1949, in full_dispatch_request
    rv = self.dispatch_request()
  File "/home/nurbek/Desktop/microblog/env/lib/python3.7/site-packages/flask/app.py", line 1935, in dispatch_request
    return self.view_functions[rule.endpoint](**req.view_args)
  File "/home/nurbek/Desktop/microblog/app/routes.py", line 22, in index
    posts = current_user.followed_posts().all()
  File "/home/nurbek/Desktop/microblog/env/lib/python3.7/site-packages/werkzeug/local.py", line 347, in __getattr__
    return getattr(self._get_current_object(), name)
AttributeError: 'User' object has no attribute 'followed_posts'
2020-04-06 19:22:06,311 INFO: Microblog [in /home/nurbek/Desktop/microblog/app/__init__.py: 48]
